2024-12-03 08:50:44,342 - ERROR - An error occurred during the ETL process:
2024-12-03 08:50:44,342 - ERROR - Error message: (pymysql.err.OperationalError) (2003, "Can't connect to MySQL server on 'localhost' ([Errno 111] Connection refused)")
(Background on this error at: https://sqlalche.me/e/20/e3q8)
2024-12-03 08:50:44,343 - ERROR - Stack trace:
2024-12-03 08:50:44,734 - ERROR - Traceback (most recent call last):
  File "/home/blackmoor/jupyter-env/lib/python3.8/site-packages/pymysql/connections.py", line 649, in connect
    sock = socket.create_connection(
  File "/usr/lib/python3.8/socket.py", line 808, in create_connection
    raise err
  File "/usr/lib/python3.8/socket.py", line 796, in create_connection
    sock.connect(sa)
ConnectionRefusedError: [Errno 111] Connection refused

During handling of the above exception, another exception occurred:

Traceback (most recent call last):
  File "/home/blackmoor/jupyter-env/lib/python3.8/site-packages/sqlalchemy/engine/base.py", line 146, in __init__
    self._dbapi_connection = engine.raw_connection()
  File "/home/blackmoor/jupyter-env/lib/python3.8/site-packages/sqlalchemy/engine/base.py", line 3302, in raw_connection
    return self.pool.connect()
  File "/home/blackmoor/jupyter-env/lib/python3.8/site-packages/sqlalchemy/pool/base.py", line 449, in connect
    return _ConnectionFairy._checkout(self)
  File "/home/blackmoor/jupyter-env/lib/python3.8/site-packages/sqlalchemy/pool/base.py", line 1263, in _checkout
    fairy = _ConnectionRecord.checkout(pool)
  File "/home/blackmoor/jupyter-env/lib/python3.8/site-packages/sqlalchemy/pool/base.py", line 712, in checkout
    rec = pool._do_get()
  File "/home/blackmoor/jupyter-env/lib/python3.8/site-packages/sqlalchemy/pool/impl.py", line 180, in _do_get
    self._dec_overflow()
  File "/home/blackmoor/jupyter-env/lib/python3.8/site-packages/sqlalchemy/util/langhelpers.py", line 146, in __exit__
    raise exc_value.with_traceback(exc_tb)
  File "/home/blackmoor/jupyter-env/lib/python3.8/site-packages/sqlalchemy/pool/impl.py", line 177, in _do_get
    return self._create_connection()
  File "/home/blackmoor/jupyter-env/lib/python3.8/site-packages/sqlalchemy/pool/base.py", line 390, in _create_connection
    return _ConnectionRecord(self)
  File "/home/blackmoor/jupyter-env/lib/python3.8/site-packages/sqlalchemy/pool/base.py", line 674, in __init__
    self.__connect()
  File "/home/blackmoor/jupyter-env/lib/python3.8/site-packages/sqlalchemy/pool/base.py", line 901, in __connect
    pool.logger.debug("Error on connect(): %s", e)
  File "/home/blackmoor/jupyter-env/lib/python3.8/site-packages/sqlalchemy/util/langhelpers.py", line 146, in __exit__
    raise exc_value.with_traceback(exc_tb)
  File "/home/blackmoor/jupyter-env/lib/python3.8/site-packages/sqlalchemy/pool/base.py", line 896, in __connect
    self.dbapi_connection = connection = pool._invoke_creator(self)
  File "/home/blackmoor/jupyter-env/lib/python3.8/site-packages/sqlalchemy/engine/create.py", line 643, in connect
    return dialect.connect(*cargs, **cparams)
  File "/home/blackmoor/jupyter-env/lib/python3.8/site-packages/sqlalchemy/engine/default.py", line 621, in connect
    return self.loaded_dbapi.connect(*cargs, **cparams)
  File "/home/blackmoor/jupyter-env/lib/python3.8/site-packages/pymysql/connections.py", line 361, in __init__
    self.connect()
  File "/home/blackmoor/jupyter-env/lib/python3.8/site-packages/pymysql/connections.py", line 716, in connect
    raise exc
pymysql.err.OperationalError: (2003, "Can't connect to MySQL server on 'localhost' ([Errno 111] Connection refused)")

The above exception was the direct cause of the following exception:

Traceback (most recent call last):
  File "/tmp/ipykernel_2827/2419377042.py", line 16, in <module>
    df.to_sql('students', con=engine, if_exists='replace', index=False)  # Replace 'students' with your table name
  File "/home/blackmoor/jupyter-env/lib/python3.8/site-packages/pandas/core/generic.py", line 2878, in to_sql
    return sql.to_sql(
  File "/home/blackmoor/jupyter-env/lib/python3.8/site-packages/pandas/io/sql.py", line 768, in to_sql
    with pandasSQL_builder(con, schema=schema, need_transaction=True) as pandas_sql:
  File "/home/blackmoor/jupyter-env/lib/python3.8/site-packages/pandas/io/sql.py", line 832, in pandasSQL_builder
    return SQLDatabase(con, schema, need_transaction)
  File "/home/blackmoor/jupyter-env/lib/python3.8/site-packages/pandas/io/sql.py", line 1539, in __init__
    con = self.exit_stack.enter_context(con.connect())
  File "/home/blackmoor/jupyter-env/lib/python3.8/site-packages/sqlalchemy/engine/base.py", line 3278, in connect
    return self._connection_cls(self)
  File "/home/blackmoor/jupyter-env/lib/python3.8/site-packages/sqlalchemy/engine/base.py", line 148, in __init__
    Connection._handle_dbapi_exception_noconnection(
  File "/home/blackmoor/jupyter-env/lib/python3.8/site-packages/sqlalchemy/engine/base.py", line 2442, in _handle_dbapi_exception_noconnection
    raise sqlalchemy_exception.with_traceback(exc_info[2]) from e
  File "/home/blackmoor/jupyter-env/lib/python3.8/site-packages/sqlalchemy/engine/base.py", line 146, in __init__
    self._dbapi_connection = engine.raw_connection()
  File "/home/blackmoor/jupyter-env/lib/python3.8/site-packages/sqlalchemy/engine/base.py", line 3302, in raw_connection
    return self.pool.connect()
  File "/home/blackmoor/jupyter-env/lib/python3.8/site-packages/sqlalchemy/pool/base.py", line 449, in connect
    return _ConnectionFairy._checkout(self)
  File "/home/blackmoor/jupyter-env/lib/python3.8/site-packages/sqlalchemy/pool/base.py", line 1263, in _checkout
    fairy = _ConnectionRecord.checkout(pool)
  File "/home/blackmoor/jupyter-env/lib/python3.8/site-packages/sqlalchemy/pool/base.py", line 712, in checkout
    rec = pool._do_get()
  File "/home/blackmoor/jupyter-env/lib/python3.8/site-packages/sqlalchemy/pool/impl.py", line 180, in _do_get
    self._dec_overflow()
  File "/home/blackmoor/jupyter-env/lib/python3.8/site-packages/sqlalchemy/util/langhelpers.py", line 146, in __exit__
    raise exc_value.with_traceback(exc_tb)
  File "/home/blackmoor/jupyter-env/lib/python3.8/site-packages/sqlalchemy/pool/impl.py", line 177, in _do_get
    return self._create_connection()
  File "/home/blackmoor/jupyter-env/lib/python3.8/site-packages/sqlalchemy/pool/base.py", line 390, in _create_connection
    return _ConnectionRecord(self)
  File "/home/blackmoor/jupyter-env/lib/python3.8/site-packages/sqlalchemy/pool/base.py", line 674, in __init__
    self.__connect()
  File "/home/blackmoor/jupyter-env/lib/python3.8/site-packages/sqlalchemy/pool/base.py", line 901, in __connect
    pool.logger.debug("Error on connect(): %s", e)
  File "/home/blackmoor/jupyter-env/lib/python3.8/site-packages/sqlalchemy/util/langhelpers.py", line 146, in __exit__
    raise exc_value.with_traceback(exc_tb)
  File "/home/blackmoor/jupyter-env/lib/python3.8/site-packages/sqlalchemy/pool/base.py", line 896, in __connect
    self.dbapi_connection = connection = pool._invoke_creator(self)
  File "/home/blackmoor/jupyter-env/lib/python3.8/site-packages/sqlalchemy/engine/create.py", line 643, in connect
    return dialect.connect(*cargs, **cparams)
  File "/home/blackmoor/jupyter-env/lib/python3.8/site-packages/sqlalchemy/engine/default.py", line 621, in connect
    return self.loaded_dbapi.connect(*cargs, **cparams)
  File "/home/blackmoor/jupyter-env/lib/python3.8/site-packages/pymysql/connections.py", line 361, in __init__
    self.connect()
  File "/home/blackmoor/jupyter-env/lib/python3.8/site-packages/pymysql/connections.py", line 716, in connect
    raise exc
sqlalchemy.exc.OperationalError: (pymysql.err.OperationalError) (2003, "Can't connect to MySQL server on 'localhost' ([Errno 111] Connection refused)")
(Background on this error at: https://sqlalche.me/e/20/e3q8)

